Workbook

Sheet Focal Point Tracking
A1: Submission Checklist 28th November
A2: Principals | B2: Focal Points submitted
A3: Admin. UNDP | B3: yes
A4: ASG DCO | B4: yes
A5: CDC​ | B5: yes
A6: Chair DTN | B6: yes
A7: Chair HLCM​ | B7: yes
A8: Co-Chairs BIG | B8: yes | D8: =54%*87 -> 46.98
A9: DSG​ | B9: yes
A10: ED UN Women | B10: yes
A11: ED UNAIDS | B11: yes
A12: ED UNFPA | B12: yes
A13: ED UNICEF | B13: yes
A14: ED UNITAR | B14: yes
A15: ED UNOPS | B15: yes
A16: ED WFP | B16: yes
A17: ES ECA​ | B17: yes
A18: ES UNFCCC | B18: yes
A19: HC OHCHR | B19: yes
A20: Rector UNU | B20: yes
... A36: USG UNODC | B36: yes
B38: {=COUNTIF(Table2[[Focal Points submitted ]], yes)} -> 0

Sheet UN80 Action Plan (2)
A1: FileSystemObjectType | B1: Id | C1: ServerRedirectedEmbedUri | D1: ServerRedirectedEmbedUrl | E1: ContentTypeId | F1: Title | G1: OData__ColorTag | H1: ComplianceAssetId | I1: Action No. | J1: Work Package | K1: Indicative Action | L1: WP Leads | M1: Milestone 1 | N1: Milestone 1 Deadline | O1: Action Lead(s) | P1: Action Support(s) | Q1: Master-List-ID | R1: Milestone Final | S1: Milestone Final Deadline | T1: ID2 | U1: Modified | V1: Created | W1: AuthorId | X1: EditorId | Y1: OData__UIVersionString | Z1: Attachments | AA1: GUID
A2: 0 | B2: 1 | E2: 0x0100B7189DADE8EA1A40B9BF8DA45310AFE600A178D82D6E6846409061C607AC5C63EE | I2: A01 | J2: WP1: Peace operations (task delegation; review) | K2: Delegate relevant programmatic tasks such as rule of law, governance and child protection – and the associated resources – to UN system entities best equipped to deliver them | L2: USG DPPA;USG DPO | M2: With respect toUSGs DiCarlo and Lacroix would lead, with the participation of UNDP, OCHA, DCO, OHCHR, PBSO, OROLSI, UNICEF, UN Women, and the SRSGs CAAC and SVC | O2: USG Lacroix; USG DiCarlo | P2: David Haeri, Director, DPET, DPO; Asif Khan, Diector, PMD, DPPA | Q2: 14 | T2: 1 | U2: 45989.688 | V2: 45967.006 | W2: 10 | X2: 222 | Y2: 10.0 | Z2: FALSE | AA2: e0b494ac-2ecf-4531-ad3e-a1c996179786
A3: 0 | B3: 2 | E3: 0x0100B7189DADE8EA1A40B9BF8DA45310AFE600A178D82D6E6846409061C607AC5C63EE | I3: A02 | J3: WP1: Peace operations (task delegation; review) | K3: Present comprehensive proposal for the reset of peace operations to Member States upon conclusion of the review mandated by the Pact for the Future | L3: USG DPPA;USG DPO | M3: Review of the future of peace operations completed | N3: 46111.917 | O3: USGs DPPA and DPO, Rosemary DiCarlo and Jean-Pierre Lacroix | P3: Directors PMD and DPET, Asif R. Khan and David Haeri | Q3: 15 | R3: Review of the future of peace operations completed | S3: 46111.917 | T3: 2 | U3: 45987.719 | V3: 45967.006 | W3: 10 | X3: 197 | Y3: 5.0 | Z3: FALSE | AA3: 0a9ea861-8ccc-43e8-ab8c-f6dc51658417
A4: 0 | B4: 3 | E4: 0x0100B7189DADE8EA1A40B9BF8DA45310AFE600A178D82D6E6846409061C607AC5C63EE | I4: A03 | J4: WP2: New Humanitarian Compact | K4: Streamline Humanitarian Needs and Response Plans to become shorter and sharper | L4: USG OCHA | Q4: 16 | T4: 3 | U4: 45973.65 | V4: 45967.006 | W4: 10 | X4: 10 | Y4: 6.0 | Z4: FALSE | AA4: 21c7739b-702b-4143-be35-401ff3713af0
A5: 0 | B5: 4 | E5: 0x0100B7189DADE8EA1A40B9BF8DA45310AFE600A178D82D6E6846409061C607AC5C63EE | I5: A04 | J5: WP2: New Humanitarian Compact | K5: Integrate global supply chains, coordinating procurement of key items, pool use of global freight and logistics, and unbranded in-country services open to the entire UN system | L5: USG OCHA | Q5: 17 | T5: 4 | U5: 45973.65 | V5: 45967.006 | W5: 10 | X5: 10 | Y5: 6.0 | Z5: FALSE | AA5: 7bf06f11-c783-407f-b724-f6eba4e2c925
A6: 0 | B6: 5 | E6: 0x0100B7189DADE8EA1A40B9BF8DA45310AFE600A178D82D6E6846409061C607AC5C63EE | I6: A05 | J6: WP2: New Humanitarian Compact | K6: Scale common services with a Global Services Hub and interoperable digital platforms to help consolidate surge rosters, logistics, security, telecoms and engineering support | L6: USG OCHA | Q6: 18 | T6: 5 | U6: 45967.006 | V6: 45967.006 | W6: 10 | X6: 10 | Y6: 1.0 | Z6: FALSE | AA6: 5897e117-f5fb-4f90-97b9-a4a40228e5ad
A7: 0 | B7: 6 | E7: 0x0100B7189DADE8EA1A40B9BF8DA45310AFE600A178D82D6E6846409061C607AC5C63EE | I7: A06 | J7: WP2: New Humanitarian Compact | K7: Initiate new Humanitarian Data Collaborative, to scale common platforms, collective financing, shared centres, capacities and standards | L7: USG OCHA | Q7: 20 | T7: 6 | U7: 45967.006 | V7: 45967.006 | W7: 10 | X7: 10 | Y7: 1.0 | Z7: FALSE | AA7: 750e3ec7-c96a-4272-90df-edc81a644fec
A8: 0 | B8: 7 | E8: 0x0100B7189DADE8EA1A40B9BF8DA45310AFE600A178D82D6E6846409061C607AC5C63EE | I8: A07 | J8: WP2: New Humanitarian Compact | K8: Initiate Collaborative Humanitarian Diplomacy Initiative to bring agencies together under the coordination of the Emergency Relief Coordinator | L8: USG OCHA | Q8: 21 | T8: 7 | U8: 45967.006 | V8: 45967.006 | W8: 10 | X8: 10 | Y8: 1.0 | Z8: FALSE | AA8: 29159a3e-0b0b-46fd-b622-401cb5c9b3a6
A9: 0 | B9: 8 | E9: 0x0100B7189DADE8EA1A40B9BF8DA45310AFE600A178D82D6E6846409061C607AC5C63EE | I9: A08 | J9: WP2: New Humanitarian Compact | K9: Align agencies’ responsibilities: FAO/WFP/IFAD on food security | L9: USG OCHA | Q9: 22 | T9: 8 | U9: 45967.006 | V9: 45967.006 | W9: 10 | X9: 10 | Y9: 1.0 | Z9: FALSE | AA9: ed9ca06d-3cbe-4227-b153-bb81fbddc316
A10: 0 | B10: 9 | E10: 0x0100B7189DADE8EA1A40B9BF8DA45310AFE600A178D82D6E6846409061C607AC5C63EE | I10: A09 | J10: WP2: New Humanitarian Compact | K10: Align agencies’ responsibilities: UNHCR/IOM on joint institutional approaches (incl. route-based programming) | L10: USG OCHA | Q10: 23 | T10: 9 | U10: 45967.006 | V10: 45967.006 | W10: 10 | X10: 10 | Y10: 1.0 | Z10: FALSE | AA10: d4ddc385-4167-4c55-9c90-104a9215d64a
A11: 0 | B11: 10 | E11: 0x0100B7189DADE8EA1A40B9BF8DA45310AFE600A178D82D6E6846409061C607AC5C63EE | I11: A10 | J11: WP2: New Humanitarian Compact | K11: Align agencies’ responsibilities: UNICEF/WFP/UNHCR/IOM on beneficiary data | L11: USG OCHA | Q11: 24 | T11: 10 | U11: 45967.006 | V11: 45967.006 | W11: 10 | X11: 10 | Y11: 1.0 | Z11: FALSE | AA11: 3a61ded2-8559-448b-8c36-6c7ac87e35e1
A12: 0 | B12: 11 | E12: 0x0100B7189DADE8EA1A40B9BF8DA45310AFE600A178D82D6E6846409061C607AC5C63EE | I12: A11 | J12: WP2: New Humanitarian Compact | K12: Align agencies’ responsibilities: WHO/UNICEF/WFP on health and nutrition | L12: USG OCHA | Q12: 25 | T12: 11 | U12: 45967.006 | V12: 45967.006 | W12: 10 | X12: 10 | Y12: 1.0 | Z12: FALSE | AA12: 699c9758-d4dc-4e87-b1ef-99265d6e0c99
A13: 0 | B13: 12 | E13: 0x0100B7189DADE8EA1A40B9BF8DA45310AFE600A178D82D6E6846409061C607AC5C63EE | I13: A12 | J13: WP3: UNDP/UNOPS | K13: Conduct a thorough assessment of the benefits of a merger between UNDP and UNOPS; analysis to be presented to the Executive Boards in February 2026 | L13: DSG;Administrator UNDP;ED UNOPS | M13: • Draft initial assessment analysis of the ‘as is’ with high level merger options, pros, cons, risk analysis for internal consultations | N13: 46040.958 | O13: 1. Amina Mohammed, DSG, amina.mohammed@un.org 2. Jorge Moreira Da Silva, USG – UNOPS, jorge.moreiradasilva@unops.org 3. Alexander de Croo, USG – UNDP, alexander.de.croo@undp.org | P13: 1. Sonja Leighton-Kone, ASG - UNOPS, sonjalk@unops.org 2. Linda Maguire, ASG - UNDP, linda.maguire@undp.org 3. Rahul Malhotra, Director New York Office, UNOPS, rahulm@unops.org 2.4. Fiona Bayat-Renoux, Deputy Chief of Staff, UNDP, Fiona.bayat-renoux@undp.org 3.5. Jean-Philippe Bernardini, Senior Political Affairs Officer, EOSG, Bernardini@un.org | Q13: 26 | R13: Thorough assessment of selected option(s) provided to Member States and guidance given through a General Assembly decision | S13: 46386.958 | T13: 12 | U13: 45989.913 | V13: 45967.006 | W13: 10 | X13: 125 | Y13: 4.0 | Z13: FALSE | AA13: d14b25b6-baf6-46b1-bc3a-c646635fff65
A14: 0 | B14: 13 | E14: 0x0100B7189DADE8EA1A40B9BF8DA45310AFE600A178D82D6E6846409061C607AC5C63EE | I14: A13 | J14: WP4: UNFPA/UN Women | K14: Conduct a thorough assessment of the benefits of a merger of UNFPA and UN Women and their respective mandates | L14: DSG;ED UNFPA;ED UN Women | M14: Strategic merger assessment is completed for internal consultations, including risk/benefit considerations | N14: 46052.958 | O14: Amina Mohammed, DSG, Amina.mohammed@un.org Sima Bahous, Executive Director, UN Women sima.bahous@unwomen.org Diene Keita, Executive Director, UNFPA, Keita@unfpa.org | P14: Jean Philippe Bernardini, Senior Political Affairs Officer, bernardini@un.org Sam Choritz, Chief of Staff, UNFPA, choritz@unfpa.org Mohammad Naciri, Chief of Staff, UN Women, mohammad.naciri@unwomen.org | Q14: 27 | R14: By mid-2026, a thorough assessment is provided to Member States for a General Assembly decision | S14: 46386.958 | T14: 13 | U14: 45992.803 | V14: 45967.006 | W14: 10 | X14: 83 | Y14: 13.0 | Z14: FALSE | AA14: d9e3af62-a6c8-4989-be12-c94e236b40b4
A15: 0 | B15: 14 | E15: 0x0100B7189DADE8EA1A40B9BF8DA45310AFE600A178D82D6E6846409061C607AC5C63EE | I15: A14 | J15: WP4: UNFPA/UN Women | K15: Conduct a thorough assessment to consider options to optimize normative functions of UNFPA on population statistics and related activities, including those currently undertaken by DESA | L15: DSG;ED UNFPA;ED UN Women | M15: Options for optimization of the UN’s work on population statistics and related activities are finalized for SG consideration and integrated in merger analysis | N15: 46052.958 | O15: 1. Amina Mohammed, DSG, Amina.mohammed@un.org 2. Sima Bahous, Executive Director, UN Women sima.bahous@unwomen.org 3. Diene Keita, Executive Director, UNFPA, Keita@unfpa.org 4. USG Li Junhua, USG DESA, junhua.li@un.org | P15: 1. Jean Philippe Bernardini, Senior Political Affairs Officer, bernardini@un.org 2. Sam Choritz, Chief of Staff, UNFPA, choritz@unfpa.org 3. Mohammad Naciri, Chief of Staff, UN Women, mohammad.naciri@unwomen.org | Q15: 28 | R15: A final assessment is integrated into the UNWomen/UNFPA merger process, as per timelines above. | S15: 46386.958 | T15: 14 | U15: 45992.805 | V15: 45967.006 | W15: 10 | X15: 83 | Y15: 7.0 | Z15: FALSE | AA15: 4d7a9de4-0cc8-4366-b8c4-5dd9982cf91a
A16: 0 | B16: 15 | E16: 0x0100B7189DADE8EA1A40B9BF8DA45310AFE600A178D82D6E6846409061C607AC5C63EE | I16: A15 | J16: WP5: UNCT reconfiguration | K16: Propose a model to reconfigure country teams via system-wide working group, chaired by the Deputy Secretary-General | L16: DSG | M16: Outline of the draft proposals presented to the Secretary-General for guidance | N16: 46029.958 | O16: 1. Amina J. Mohammed, DSG, Amina.mohammed@un.org 2. Jorge Moreira Da Silva, USG – UNOPS, jorge.moreiradasilva@unops.org | P16: 1. Rahul Malhorta, Director, UNOPS, rahulm@unops.org 2. Jean Philippe Bernardini, Senior Political Affairs Officer, bernardini@un.org | Q16: 39 | R16: Member States take action/decide on final set of proposals presented by the SG (report finalized by 31 May 2026 – TBC, depending next reporting cycle) | T16: 15 | U16: 45992.802 | V16: 45967.006 | W16: 10 | X16: 83 | Y16: 4.0 | Z16: FALSE | AA16: 42617088-b056-4e06-9d9e-b79391e942cc
A17: 0 | B17: 16 | E17: 0x0100B7189DADE8EA1A40B9BF8DA45310AFE600A178D82D6E6846409061C607AC5C63EE | I17: A16 | J17: WP5: UNCT reconfiguration | K17: Strengthen and recalibrate the Resident Coordinator system to better leverage knowledge hubs, expertise-on-demand, and non-resident entities | L17: DSG | M17: The parameters for the recalibration of the RC system are defined and being consulted with Member States (e.g. change in DCO structure, more tailored approach) | N17: 46052.958 | O17: 1. Amina J. Mohammed, DSG, Amina.mohammed@un.org 2. Oscar Fernandez-Taranco, DCO fernandez-taranco@un.org | P17: 1. Jean Philippe Bernardini, Senior Political Affairs Officer, bernardini@un.org | Q17: 40 | R17: All measures to recalibrate the RC system (DCO 2.0) are implemented and a decision to enhance the funding model of the RC system is successfully tabled in the | S17: 46386.958 | T17: 16 | U17: 45992.802 | V17: 45967.006 | W17: 10 | X17: 83 | Y17: 6.0 | Z17: FALSE | AA17: ea519c52-4d19-4969-b210-4d312d140e95
A18: 0 | B18: 17 | E18: 0x0100B7189DADE8EA1A40B9BF8DA45310AFE600A178D82D6E6846409061C607AC5C63EE | I18: A17 | J18: WP6: Regional reset | K18: Establish a system-wide working group, chaired by the Deputy Secretary-General, to develop proposals on how to advance a reset of regional capacities for sustainable development, incl. on how to institutionalize Regional Integrated Platforms | L18: DSG | M18: system-wide working group convened and draft outline finalized and shared with the Secretary-General for guidance | N18: 46029.958 | O18: 1. Amina J. Mohammed, DSG, Amina.mohammed@un.org 2. Izumi Nakamitsu, USG – ODA, nakamitsu@un.org | P18: 1. Jean Philippe Bernardini, Senior Political Affairs Officer, bernardini@un.org | Q18: 36 | R18: Aspects of the regional reset under SG prerogative are implemented and decisions taken by Member States on aspects requiring new mandates (report May 2026 -TBC) | T18: 17 | U18: 45990.085 | V18: 45967.006 | W18: 10 | X18: 274 | Y18: 4.0 | Z18: FALSE | AA18: 4a2996a2-167e-41a3-a9f6-2df8237a6e8f
A19: 0 | B19: 18 | E19: 0x0100B7189DADE8EA1A40B9BF8DA45310AFE600A178D82D6E6846409061C607AC5C63EE | I19: A18 | J19: WP6: Regional reset | K19: Systematize the practice of hosting regional capacities within the Regional Economic Commissions, starting with DCO regional directors and teams | L19: DSG | M19: Develop initial proposals for co-hosting for further consultation, taking into consideration the unique regional needs and contexts. | N19: 46052.958 | O19: 1. Amina J. Mohammed, DSG, Amina.mohammed@un.org 2. Izumi Nakamitsu, USG – ODA, nakamitsu@un.org 3. Oscar Fernandez Taranco, ASG – DCO, fernandez-taranco@un.org | P19: 4. Jean Philippe Bernardini, Senior Political Affairs Officer, bernardini@un.org 5. Nadia Hadi, Chief of Staff DCO, hadin@un.org 6. Thilmeeza Hussain, Director, Regional Commission Office, thilmeeza.hussain@un.org | Q19: 37 | R19: Relocation of respective offices to be hosted by RECs is complete or ongoing, according to implementation plan developed for each region by 29 May 2026. | T19: 18 | U19: 45990.087 | V19: 45967.006 | W19: 10 | X19: 274 | Y19: 4.0 | Z19: FALSE | AA19: f1aaf1b1-05df-411a-8e7e-283247847158
A20: 0 | B20: 19 | E20: 0x0100B7189DADE8EA1A40B9BF8DA45310AFE600A178D82D6E6846409061C607AC5C63EE | I20: A19 | J20: WP7: Joint knowledge hubs | K20: Establish Joint Knowledge Hubs to pool knowledge on key issues spread across UN development system entities and avoid duplications, including finding the best placed entities to co-leads (through joint mechanisms) | L20: USG DESA;SG UNCTAD | M20: The first meeting endorsed the concept note, agreed on hub list with leads, and committed to distinct value and collaboration with UN mechanisms. | O20: Rebeca Grynspan, Secretary-General of UNCTAD, rebeca.grynspan@unctad.org LI Junhua, Under-Secretary-General of DESA, junhua.li@un.org | P20: Adnan Issa, Director, Programme Management, UNCTAD, issa@unctad.org Wai Min Kwok, Acting Chief, Office of the USG, DESA, kwok@un.org Carlos Razo, Senior Coordinator, Office of the Secretary General, UNCTAD, carlos.razo@un.org Guenther Gross, Senior Programme Management Officer, Office of the USG, DESA, gross1@un.org | Q20: 33 | R20: Established hubs deliver coherent, efficient UN-wide support, integrating data and knowledge for policy coherence and innovative solutions. | T20: 19 | U20: 45989.922 | V20: 45967.006 | W20: 10 | X20: 277 | Y20: 4.0 | Z20: FALSE | AA20: 1f4433d6-a917-4565-8264-ba1ac0c0274e
A21: 0 | B21: 20 | E21: 0x0100B7189DADE8EA1A40B9BF8DA45310AFE600A178D82D6E6846409061C607AC5C63EE | I21: A20 | J21: WP8: Expertise-on-demand mechanism | K21: Create a pro-active mechanism UN system-wide expertise on demand, particularly from specialized agencies and non-resident entities | L21: SG ITU | M21: Concept endorsed. Legal/financial assessment, catalogue design, & demand protocol and arrangements. | N21: 46052.958 | O21: Leads: ITU: Ms. Doreen Bogdan-Martin, Secretary-General (sgo@itu.int) UNDP Invited to co-Lead: Haoliang Xu, Acting Administrator (haoliang.xu@undp.org) Members: FAO: Mr. Qu Dongyu, Director General (director-general@fao.org; dongyu.qu@fao.org) ICAO: Mr. Juan Carlos Salazar, Secretary-General (OSGinbox@icao.int; jsalazar@icao.int) ILO: Mr. Gilbert F. Houngbo, Director General (ILODirector-General@ilo.org) UNESCO: Mr Khaled El-Enany, Director-General (dg.secretariat@unesco.org) UNIDO: Gerd Müller, Director General (ODG@unido.org) WMO: Ms Celeste Saulo, Secretary-General (sgomm@wmo.int) ITC: Ms. Pamela Coke-Hamilton, Executive Director and ASG (cokehamilton@intracen.org); front office: Ascension Carrasco Rodriguez (carrasco@intracen.org) UN Women: Sima Bahous, Executive Director. Sima Sami Bahous (sima.bahous@unwomen.org) Regional Commissions: Mr. Claver Gatete, Coordinator of the Regional Commissions, ECA Executive Secretary (cgatete@un.org) Ms. Tatiana Molcean, Executive Secretary of ECE (tatiana.molcean@un.org) Mr. Mourad Wahba, Acting Executive of ESCWA Secretary (mourad.wahba@un.org) In addition, invited to contribute as standing members subject to confirmation: WHO: Mr. Tedros Adhanom Ghebreyesus, Director General (dgoffice@who.int; drtedros@who.int) tbc UNCTAD: Ms. Rebeca Grynspan, Secretary-General (rebeca.grynspan@unctad.org) tbc | P21: ITU: Tomas Lamanauskas, Deputy Secretary-General (dsg@itu.int) UNDP: Linda Maquire, Asst Secretary General and Director, Bureau for Management Services (linda.maguire@undp.org) FAO: Beth Crawford, Assistant Director-General/Director, Office of Strategy, Programme and Budget (beth.crawford@fao.org ) ICAO: Michiel Vreedenburgh, Chief Transformation Officer (MVreedenburgh@icao.int) ILO: Ms. Laura Thompson, Assistant Director General, External and Corporate Relations (thompsonl@ilo.org) UNESCO: Jennifer Linkins, Assistant Director-General for Administration and Management (j.linkins@unesco.org) UNIDO: Ms. Cecilia Ugaz Estrada, Deputy to the Director General (C.UGAZESTRADA@unido.org) tbc WMO: Ko Barrett, DSG (dsgo@wmo.int) ITC: Mr. Mondher Mimouni, Director, Division of Market Development (mimouni@intracen.org) UN Women: Nyaradzayi Gumbonzvanda. Deputy Executive Director Normative Support, System Coordination, Programme Results (n.gumbonzvanda@unwomen.org) Regional Commissions: Ms. Thilmeeza Hussain (thilmeeza.hussain@un.org) ECA Mr. Aboubakri Diaw (diaw2@un.org) ECA Mr. Paul John Ladd (paul.ladd@un.org) ECE Ms. Maisaa Youssef (youssef8@un.org) ESCWA Ms. Riwa Nasreddine (nasreddine@un.org) ESCWA Support/Advisor: SA Reform Jens Christian Wandel, USG and Special Adviser to the Secretary-General on Reforms (jens.wandel@un.org) In addition, invited to contribute as standing members subject to confirmation: ILO: Ms. Laura Thompson, Assistant Director General, External and Corporate Relations (thompsonl@ilo.org) WHO: Bruce Aylward, Senior Advisor to the Director-General (aylwardb@who.int) UNCTAD Tbc: | Q21: 34 | R21: EOD fully operational system-wide: expertise catalogue launched, protocols institutionalized, proven replacement of duplicative capacities. | S21: 46375.958 | T21: 20 | U21: 45992.707 | V21: 45967.006 | W21: 10 | X21: 109 | Y21: 15.0 | Z21: FALSE | AA21: 904d4c8d-4c80-4591-a7b8-b33df38b95d4
A22: 0 | B22: 21 | E22: 0x0100B7189DADE8EA1A40B9BF8DA45310AFE600A178D82D6E6846409061C607AC5C63EE | I22: A21 | J22: WP8: Expertise-on-demand mechanism | K22: Consolidate expertise across all pillars at the regional level as an extension of the expertise-on-demand mechanism outlined in the sustainable development pillar | L22: SG ITU | M22: Concept endorsed. Legal/financial assessment, catalogue design, & demand protocol and arrangements. | N22: 46052.958 | O22: Leads: ITU: Ms. Doreen Bogdan-Martin, Secretary-General (sgo@itu.int) UNDP Invited to co-Lead: Haoliang Xu, Acting Administrator (haoliang.xu@undp.org) Members: FAO: Mr. Qu Dongyu, Director General (director-general@fao.org; dongyu.qu@fao.org) ICAO: Mr. Juan Carlos Salazar, Secretary-General (OSGinbox@icao.int; jsalazar@icao.int) ILO: Mr. Gilbert F. Houngbo, Director General (ILODirector-General@ilo.org) UNESCO: Mr Khaled El-Enany, Director-General (dg.secretariat@unesco.org) UNIDO: Gerd Müller, Director General (ODG@unido.org) WMO: Ms Celeste Saulo, Secretary-General (sgomm@wmo.int) ITC: Ms. Pamela Coke-Hamilton, Executive Director and ASG (cokehamilton@intracen.org); front office: Ascension Carrasco Rodriguez (carrasco@intracen.org) UN Women: Sima Bahous, Executive Director. Sima Sami Bahous (sima.bahous@unwomen.org) Regional Commissions: Mr. Claver Gatete, Coordinator of the Regional Commissions, ECA Executive Secretary (cgatete@un.org) Ms. Tatiana Molcean, Executive Secretary of ECE (tatiana.molcean@un.org) Mr. Mourad Wahba, Acting Executive of ESCWA Secretary (mourad.wahba@un.org) In addition, invited to contribute as standing members subject to confirmation: WHO: Mr. Tedros Adhanom Ghebreyesus, Director General (dgoffice@who.int; drtedros@who.int) tbc UNCTAD: Ms. Rebeca Grynspan, Secretary-General (rebeca.grynspan@unctad.org) tbc | P22: ITU: Tomas Lamanauskas, Deputy Secretary-General (dsg@itu.int) UNDP: Linda Maquire, Asst Secretary General and Director, Bureau for Management Services (linda.maguire@undp.org) FAO: Beth Crawford, Assistant Director-General/Director, Office of Strategy, Programme and Budget (beth.crawford@fao.org ) ICAO: Michiel Vreedenburgh, Chief Transformation Officer (MVreedenburgh@icao.int) ILO: Ms. Laura Thompson, Assistant Director General, External and Corporate Relations (thompsonl@ilo.org) UNESCO: Jennifer Linkins, Assistant Director-General for Administration and Management (j.linkins@unesco.org) UNIDO: Ms. Cecilia Ugaz Estrada, Deputy to the Director General (C.UGAZESTRADA@unido.org) tbc WMO: Ko Barrett, DSG (dsgo@wmo.int) ITC: Mr. Mondher Mimouni, Director, Division of Market Development (mimouni@intracen.org) UN Women: Nyaradzayi Gumbonzvanda. Deputy Executive Director Normative Support, System Coordination, Programme Results (n.gumbonzvanda@unwomen.org) Regional Commissions: Ms. Thilmeeza Hussain (thilmeeza.hussain@un.org) ECA Mr. Aboubakri Diaw (diaw2@un.org) ECA Mr. Paul John Ladd (paul.ladd@un.org) ECE Ms. Maisaa Youssef (youssef8@un.org) ESCWA Ms. Riwa Nasreddine (nasreddine@un.org) ESCWA Support/Advisor: SA Reform Jens Christian Wandel, USG and Special Adviser to the Secretary-General on Reforms (jens.wandel@un.org) In addition, invited to contribute as standing members subject to confirmation: ILO: Ms. Laura Thompson, Assistant Director General, External and Corporate Relations (thompsonl@ilo.org) WHO: Bruce Aylward, Senior Advisor to the Director-General (aylwardb@who.int) UNCTAD Tbc: | Q22: 54 | R22: EOD fully operational system-wide: expertise catalogue launched, protocols institutionalized, proven replacement of duplicative capacities. | S22: 46375.958 | T22: 21 | U22: 45992.707 | V22: 45967.006 | W22: 10 | X22: 109 | Y22: 23.0 | Z22: FALSE | AA22: d96e13d9-727a-4ec0-aee0-c9b4d2b5a07f
A23: 0 | B23: 22 | E23: 0x0100B7189DADE8EA1A40B9BF8DA45310AFE600A178D82D6E6846409061C607AC5C63EE | I23: A22 | J23: WP9: Human rights group | K23: Establish a Human Rights Group comprising entities from across the UN system, led by the High Commissioner for Human Rights | L23: HC OHCHR | Q23: 42 | T23: 22 | U23: 45968.775 | V23: 45967.006 | W23: 10 | X23: 10 | Y23: 5.0 | Z23: FALSE | AA23: 74a80a22-72b9-4584-bb25-af27ed6d0ed3
A24: 0 | B24: 23 | E24: 0x0100B7189DADE8EA1A40B9BF8DA45310AFE600A178D82D6E6846409061C607AC5C63EE | I24: A23 | J24: WP10: Senior management coordination forums | K24: Review top management fora to ease the coordination burden for senior leaders and ensure coherent action across pillar, incl. CEB, IASC, UNSDG, EC | L24: USG Policy | Q24: 43 | T24: 23 | U24: 45968.775 | V24: 45967.007 | W24: 10 | X24: 10 | Y24: 6.0 | Z24: FALSE | AA24: cc3b8bbb-212e-43be-9da2-2c0fcc973a65
A25: 0 | B25: 24 | E25: 0x0100B7189DADE8EA1A40B9BF8DA45310AFE600A178D82D6E6846409061C607AC5C63EE | I25: A24 | J25: WP10: Senior management coordination forums | K25: Consider proposals to unify administrative backend support and streamline duplicative agendas without affecting core substantive competencies | L25: USG Policy | Q25: 44 | T25: 24 | U25: 45967.007 | V25: 45967.007 | W25: 10 | X25: 10 | Y25: 1.0 | Z25: FALSE | AA25: 52dc6857-c733-416e-a55e-d414e90e0d00
A26: 0 | B26: 25 | E26: 0x0100B7189DADE8EA1A40B9BF8DA45310AFE600A178D82D6E6846409061C607AC5C63EE | I26: A25 | J26: WP10: Senior management coordination forums | K26: Bring together all Headquarters coordination on country-specific, cross-pillar approaches to crisis prevention and centre capacities around the Regional Monthly Review platform | L26: USG Policy | Q26: 46 | T26: 25 | U26: 45967.007 | V26: 45967.007 | W26: 10 | X26: 10 | Y26: 1.0 | Z26: FALSE | AA26: f8be6931-b546-48fb-8f1a-90e1f46968b5
A27: 0 | B27: 26 | E27: 0x0100B7189DADE8EA1A40B9BF8DA45310AFE600A178D82D6E6846409061C607AC5C63EE | I27: A26 | J27: WP10: Senior management coordination forums | K27: Review existing interagency task forces and working groups | L27: USG Policy | Q27: 47 | T27: 26 | U27: 45967.007 | V27: 45967.007 | W27: 10 | X27: 10 | Y27: 1.0 | Z27: FALSE | AA27: 4517f49b-9a20-45f6-a240-ed97b6217e3b
A28: 0 | B28: 27 | E28: 0x0100B7189DADE8EA1A40B9BF8DA45310AFE600A178D82D6E6846409061C607AC5C63EE | I28: A27 | J28: WP11: Special envoy review | K28: Review and make proposals to Member States regarding SG’s some 30 special envoys, representatives, coordinators and advisers, both thematic and geographic | L28: USG Policy | Q28: 45 | T28: 27 | U28: 45967.007 | V28: 45967.007 | W28: 10 | X28: 10 | Y28: 1.0 | Z28: FALSE | AA28: ad2ff997-e7a8-4052-bf4f-10857483d502
A29: 0 | B29: 28 | E29: 0x0100B7189DADE8EA1A40B9BF8DA45310AFE600A178D82D6E6846409061C607AC5C63EE | I29: A28 | J29: WP12: Regional integrated platforms | K29: Establish lean Regional Integrated Platforms to unite regional leaders across all pillars around joint plans, strategies, crisis response and resource mobilization for cross-cutting issues | L29: ASG DCO;DSG | M29: System-wide working group convened and draft Outline on regional reset to be shared with the SG for guidance, reflecting cross-pillar dimensions | N29: 46029.958 | O29: 1. Amina J. Mohammed, DSG, Amina.mohammed@un.org 2. Izumi Nakamitsu, USG – ODA, nakamitsu@un.org 3. Oscar Fernandez Taranco, ASG – DCO, fernandez-taranco@un.org | P29: 1. Jean Philippe Bernardini, Senior Political Affairs Officer, bernardini@un.org | Q29: 48 | R29: Aspects of the regional reset – including RIPs - under SG prerogative are implemented and decisions taken by Member States (Report May 2026 - TBC) | S29: 46386.958 | T29: 28 | U29: 45990.09 | V29: 45967.007 | W29: 10 | X29: 274 | Y29: 2.0 | Z29: FALSE | AA29: dc3b8c87-c1d7-45fa-b222-7262821a6f7b
A30: 0 | B30: 29 | E30: 0x0100B7189DADE8EA1A40B9BF8DA45310AFE600A178D82D6E6846409061C607AC5C63EE | I30: A29 | J30: WP12: Regional integrated platforms | K30: Harmonize how UN system entities organize their regional work | L30: ASG DCO;DSG | M30: This response is being taken forward under work package 6 - the regional reset and therefore has the same milestones and action members. | Q30: 50 | T30: 29 | U30: 45990.104 | V30: 45967.007 | W30: 10 | X30: 274 | Y30: 2.0 | Z30: FALSE | AA30: 24cffaaa-3eba-446e-aae6-16a0f17f5138
A31: 0 | B31: 30 | E31: 0x0100B7189DADE8EA1A40B9BF8DA45310AFE600A178D82D6E6846409061C607AC5C63EE | I31: A30 | J31: WP13: Shared platform initiative | K31: Initiate a practical Shared Platform Initiative between DSG and ERC | L31: USG OCHA;DSG | M31: Action plan for the Shared Platform Initiative with specific timelines for immediate implementation and progress Report to the SG summarizing next steps | N31: 46052.958 | O31: 1. Amina Mohammed, Deputy Secretary-General, amina.mohammed@un.org 2. Tom Fletcher, Emergency Relief Coordinator and USG OCHA, fletcher@un.org | P31: 1. Garry Conille, Special Adviser, DCO, gconille@unicef.org 2. Edem Wosornu, Director, Crisis Response Division, OCHA, wosornu@un.org 3. Jean Philippe Bernardini, Senior Political Affairs Officer, Bernardini@un.org | Q31: 19 | R31: All initiatives rolled out and implementation finalized, as country contexts required. | S31: 46386.958 | T31: 30 | U31: 45990.093 | V31: 45967.007 | W31: 10 | X31: 274 | Y31: 2.0 | Z31: FALSE | AA31: f9391a1f-67e0-4722-b025-e496a65026f0
A32: 0 | B32: 31 | E32: 0x0100B7189DADE8EA1A40B9BF8DA45310AFE600A178D82D6E6846409061C607AC5C63EE | I32: A31 | J32: WP13: Shared platform initiative | K32: Prepare a proposal to ensure that RC/HCs and planning teams simplify Development Cooperation Frameworks, Humanitarian Response Plans, Peacebuilding Strategies and associated needs analyses for relevant settings | L32: USG OCHA;DSG | M32: Draft of the Proposal for simplifying country-level planning process where necessary (ensuring complementarity between the planning frameworks), with PBSO | N32: 46052.958 | O32: 1. Amina Mohammed, Deputy Secretary-General, amina.mohammed@un.org 2. Tom Fletcher, Emergency Relief Coordinator and USG OCHA, fletcher@un.org | P32: 1. Garry Conille, Special Adviser, DCO, gconille@unicef.org 2. Edem Wosornu, Director, Crisis Response Division, OCHA, wosornu@un.org 3. Jean Philippe Bernardini, Senior Political Affairs Officer, Bernardini@un.org | Q32: 57 | R32: Roll out of the simplified planning process and associated needs analysis system wide by July 2026 | S32: 46232.917 | T32: 31 | U32: 45990.095 | V32: 45967.007 | W32: 10 | X32: 274 | Y32: 2.0 | Z32: FALSE | AA32: 47337149-b408-4432-a000-500398c8e237
A33: 0 | B33: 32 | E33: 0x0100B7189DADE8EA1A40B9BF8DA45310AFE600A178D82D6E6846409061C607AC5C63EE | I33: A32 | J33: WP14: Unified services roadmap | K33: Prepare a Unified Services Roadmap, based on existing reform commitments and two models: some services will be provided by consolidated entities, and others through marketplaces of providers. | L33: Chair HLCM;ED WFP;Co-Chairs BIG | Q33: 63 | T33: 32 | U33: 45968.775 | V33: 45967.007 | W33: 10 | X33: 10 | Y33: 3.0 | Z33: FALSE | AA33: 7a7c388f-60ab-43ba-90cf-b7120019f75c
A34: 0 | B34: 33 | E34: 0x0100B7189DADE8EA1A40B9BF8DA45310AFE600A178D82D6E6846409061C607AC5C63EE | I34: A33 | J34: WP14: Unified services roadmap | K34: Integrate supply chains, taking the New Humanitarian Compact as the concrete starting point | L34: Chair HLCM;ED WFP;Co-Chairs BIG | Q34: 64 | T34: 33 | U34: 45967.007 | V34: 45967.007 | W34: 10 | X34: 10 | Y34: 1.0 | Z34: FALSE | AA34: acac1c02-b94b-4a0d-a18e-9847444880bc
A35: 0 | B35: 34 | E35: 0x0100B7189DADE8EA1A40B9BF8DA45310AFE600A178D82D6E6846409061C607AC5C63EE | I35: A34 | J35: WP14: Unified services roadmap | K35: Conduct assessment for integration of basic information and communication technology services, as well as payroll, human resources, finance, and enterprise resource planning (ERP) systems | L35: Chair HLCM;ED WFP;Co-Chairs BIG | Q35: 65 | T35: 34 | U35: 45967.007 | V35: 45967.007 | W35: 10 | X35: 10 | Y35: 1.0 | Z35: FALSE | AA35: 58a257ab-e9c9-4e75-ad8c-bb789d50dc7f
A36: 0 | B36: 35 | E36: 0x0100B7189DADE8EA1A40B9BF8DA45310AFE600A178D82D6E6846409061C607AC5C63EE | I36: A35 | J36: WP14: Unified services roadmap | K36: Accelerate the move toward a unified service backbone at country level; eliminate costly duplication on the ground | L36: Chair HLCM;ED WFP;Co-Chairs BIG | Q36: 78 | T36: 35 | U36: 45967.007 | V36: 45967.007 | W36: 10 | X36: 10 | Y36: 1.0 | Z36: FALSE | AA36: 144fea0a-f1d2-4250-94ce-e61a381d2b6f
A37: 0 | B37: 36 | E37: 0x0100B7189DADE8EA1A40B9BF8DA45310AFE600A178D82D6E6846409061C607AC5C63EE | I37: A36 | J37: WP14: Unified services roadmap | K37: Harmonize most indirect and programme support costs | L37: Chair HLCM;ED WFP;Co-Chairs BIG | Q37: 67 | T37: 36 | U37: 45967.007 | V37: 45967.007 | W37: 10 | X37: 10 | Y37: 1.0 | Z37: FALSE | AA37: 681c949c-4b29-47d6-af70-2839f47bb211
A38: 0 | B38: 37 | E38: 0x0100B7189DADE8EA1A40B9BF8DA45310AFE600A178D82D6E6846409061C607AC5C63EE | I38: A37 | J38: WP15: Technology | K38: Prepare a proposal to consolidate the fragmented landscape of basic cloud services, network infrastructures, office software and systems under realigned common providers that can serve the entire UN system, building on lessons from the International Computing Centre | L38: USG Policy;Chair DTN;SG ITU | Q38: 77 | T38: 37 | U38: 45967.849 | V38: 45967.007 | W38: 10 | X38: 10 | Y38: 2.0 | Z38: FALSE | AA38: 7a829912-9ce7-425f-8da2-2cd9afd99448
A39: 0 | B39: 38 | E39: 0x0100B7189DADE8EA1A40B9BF8DA45310AFE600A178D82D6E6846409061C607AC5C63EE | I39: A38 | J39: WP15: Technology | K39: Develop baseline of the current innovation landscape and a proposal for a Technology Accelerator Platform (TAP) to the Chief Executives Board | L39: USG Policy;Chair DTN;SG ITU | Q39: 62 | T39: 38 | U39: 45967.007 | V39: 45967.007 | W39: 10 | X39: 10 | Y39: 1.0 | Z39: FALSE | AA39: 979dec43-6b83-4b4b-9a81-3219ad834f2d
A40: 0 | B40: 39 | E40: 0x0100B7189DADE8EA1A40B9BF8DA45310AFE600A178D82D6E6846409061C607AC5C63EE | I40: A39 | J40: WP16: Data | K40: Prepare proposals for the Chief Executives Board at the end of October 2025 on how to guide phased implementation of Data Commons | L40: USG Policy;USG DESA;ED UNICEF | Q40: 71 | T40: 39 | U40: 45967.007 | V40: 45967.007 | W40: 10 | X40: 10 | Y40: 1.0 | Z40: FALSE | AA40: 53196679-9d32-4bc5-ae83-bafaf17b226a
...

Sheet UN80 Action Plan
A1: WP No. | B1: Work Package | C1: Action No | D1: Indicative Action | E1: WP Leads | F1: Action Lead(s) | G1: Action Support(s) | H1: ActionEntity(s) | I1: Milestone 1 | J1: Milestone 1 Deadline | K1: Milestone Final | L1: Milestone Final Deadline | M1: Sense-checked | N1: Notes
A2: 1 | B2: WP1: Peace operations (task delegation; review) | C2: 14 | D2: Delegate relevant programmatic tasks such as rule of law, governance and child protection – and the associated resources – to UN system entities best equipped to deliver them. | E2: USG DPPA;USG DPO | F2: Rosemary DiCarlo, USG DPPA, rosemary.dicarlo@un.org; Jean-Pierre Lacroix, USG DPO, jean-pierre.lacroix@un.org USGs DPPA and DPO, Rosemary DiCarlo and Jean-Pierre Lacroix, with participation from UNDP, OCHA, DCO, OHCHR, PBSO, OROLSI, UNICEF, UN Women, and the SRSGs CAAC and SVC | G2: David Haeri, Director DPET, DPO, haeri@un.org; Asif Khan, Director PMD, DPPA, khan34@un.org | H2: DPPA;DPO | I2: First discussion held. | J2: 46021 | K2: Clarification on delegation of relevant programmatic tasks. | L2: 46111 | M2: Confirmation needed | N2: Confirmation on standing members; align on ambition between milestone and report proposal; notes on PPB submission end of February.
A3: 1 | B3: WP1: Peace operations (task delegation; review) | C3: 15 | D3: Present comprehensive proposal for the reset of peace operations to Member States upon conclusion of the review mandated by the Pact for the Future. | E3: USG DPPA;USG DPO | F3: Rosemary DiCarlo, USG DPPA, rosemary.dicarlo@un.org; Jean-Pierre Lacroix, USG DPO, jean-pierre.lacroix@un.org | G3: David Haeri, Director DPET, DPO, haeri@un.org; Asif Khan, Director PMD, DPPA, khan34@un.org | H3: DPPA;DPO | I3: Review of the future of peace operations completed | J3: 46111 | K3: Review of the future of peace operations completed. | L3: 46111 | M3: Confirmation needed | N3: Confirmation on standing members; align on ambition between milestone and report proposal; notes on proposals after review and PPB submission end of February.
A4: 2 | B4: WP2: New Humanitarian Compact | C4: 16 | D4: Streamline Humanitarian Needs and Response Plans to become shorter and sharper | E4: USG OCHA | F4: Tom Fletcher, Under-Secretary-General for Humanitarian Affairs and Emergency Relief Coordinator (OCHA) - fletcher@un.org | G4: Hansjoerg Strohmeyer, Policy Director, OCHA - strohmeyerh@un.org | H4: OCHA | M4: Confirmation needed | N4: Milestones and timeline missing
A5: 2 | B5: WP2: New Humanitarian Compact | C5: 17 | D5: Integrate global supply chains, coordinating procurement of key items, pool use of global freight and logistics, and unbranded in-country services open to the entire UN system | E5: USG OCHA | F5: Tom Fletcher, Under-Secretary-General for Humanitarian Affairs and Emergency Relief Coordinator (OCHA) - fletcher@un.org Catherine Russell, Executive Director, UNICEF - crussell@unicef.org Cindy McCain, Executive Director, World Food Programme (WFP) - cindy.mccain@wfp.org Atul Khare, Under-Secretary-General for Operational Support (UN-DOS) - khare@un.org | G5: Hansjoerg Strohmeyer, Policy Director, OCHA - strohmeyerh@un.org AnneMarie Van Den Berg, Assistant-Secretary-General, Office of Supply Chain Management (OSCM), DOS - vandenberga@un.org Corinne Fleischer, Director, Supply Chain, WFP - Corinne.fleischer@wfp.org Leila Gharagozloo Pakkala, Director, Supply Divisions, UNICEF - lpakkala@unicef.org | H5: OCHA;UNICEF;WFP;DOS | I5: Interagency supply chain pilot design endorsed, and starter locations agreed | J5: 46052 | K5: Integrated UN supply chain operational across agencies, with joint procurement and shared logistics in starter countries, improving speed and cost | L5: 46386 | M5: Attention to timeline | N5: Consider final timeline earlier than December
A6: 2 | B6: WP2: New Humanitarian Compact | C6: 18 | D6: Scale common services with a Global Services Hub and interoperable digital platforms to help consolidate surge rosters, logistics, security, telecoms and engineering support | E6: USG OCHA | F6: Tom Fletcher, Under-Secretary-General for Humanitarian Affairs and Emergency Relief Coordinator (OCHA) - fletcher@un.org Filippo Grandi, United Nations High Commissioner for Refugees (UNHCR) - grandi@unhcr.org Cindy McCain, Executive Director, World Food Programme (WFP) - cindy.mccain@wfp.org | G6: Hansjoerg Strohmeyer, Policy Director, OCHA - strohmeyerh@un.org Kelly Tallman Clements - Deputy High Commissioner for Refugees, UNHCR - clements@unhcr.org Carl Skau, Deputy Executive Director and Chief Operating Officer, World Food Programme (WFP) - carl.skau@wfp.org | H6: OCHA;UNHCR;WFP | I6: Initial package of priority common services identified, drawing on existing practices (e.g. fleet, booking, engineering, security/emergency mgmt | J6: 46052 | K6: Priority common services expanded across several contexts with multiple agencies, with a review demonstrating clearer and more efficient shared delivery | L6: 46386 | M6: Attention to timeline | N6: Consider final timeline earlier than December
A7: 2 | B7: WP2: New Humanitarian Compact | C7: 20 | D7: Initiate new Humanitarian Data Collaborative, to scale common platforms, collective financing, shared centres, capacities and standards | E7: USG OCHA | F7: Tom Fletcher, Under-Secretary-General for Humanitarian Affairs and Emergency Relief Coordinator (OCHA), fletcher@un.org Filippo Grandi, United Nations High Commissioner for Refugees (UNHCR) - grandi@unhcr.org Catherine Russell, Executive Director, UNICEF - crussell@unicef.org Cindy McCain, Executive Director, World Food Programme (WFP) - cindy.mccain@wfp.org Amy Pope, Director General, International Organization for Migration (IOM) - dg@iom.int | G7: Hansjoerg Strohmeyer, Policy Director, OCHA - strohmeyerh@un.org Jean-Martin Bauer, Director, Assessments, Planning, Policy and Research, WFP - jean-martin.bauer@wfp.org | H7: OCHA;UNHCR;UNICEF;WFP;IOM | I7: Humanitarian Cluster Data Workplan agreed, with quick wins, starter countries, governance options and a joint data-sharing ambition. | J7: 46052 | K7: Humanitarian Data Collaborative established, scaling platforms, financing and shared capacities and standards. | L7: 46386 | M7: Attention to timeline | N7: Consider final timeline earlier than December
A8: 2 | B8: WP2: New Humanitarian Compact | C8: 21 | D8: Initiate Collaborative Humanitarian Diplomacy Initiative to bring agencies together under the coordination of the Emergency Relief Coordinator | E8: USG OCHA | F8: Tom Fletcher, Under-Secretary-General for Humanitarian Affairs and Emergency Relief Coordinator (OCHA) - fletcher@un.org Filippo Grandi, United Nations High Commissioner for Refugees (UNHCR) - grandi@unhcr.org Catherine Russell, Executive Director, UNICEF - crussell@unicef.org Cindy McCain, Executive Director, World Food Programme (WFP) - cindy.mccain@wfp.org Amy Pope, Director General, International Organization for Migration (IOM) - dg@iom.int | G8: Hansjoerg Strohmeyer, Policy Director, OCHA - strohmeyerh@un.org Fredrick Lee-Ohlsson, Director, OED-DIP, WFP - fredrick.lee-ohlsson@wfp.org Ted Chaiban, Deputy Executive Director, UNICEF - tchaiban@unicef.org Ugochi Daniels, Deputy Director General for Operations, International Organization for Migration (IOM) - udaniels@iom.int Shahrzad Tadjbakhsh, Director, Division of International Protection, UNHCR - tadjbakh@unhcr.org | H8: OCHA;UNHCR;UNICEF;WFP;IOM | I8: Principals’ Humanitarian Diplomacy mechanism launched, with agreed priorities, meeting cadence, and initial crisis list identified | J8: 46052 | K8: Collab. humanitarian diplomacy functioning system-wide with coordinated messaging, shared strategies and clear impact in priority crises | L8: 46386 | M8: Attention to timeline | N8: Consider final timeline earlier than December
A9: 2 | B9: WP2: New Humanitarian Compact | C9: 22 | D9: Align agencies’ responsibilities: FAO/WFP/IFAD on food security | E9: USG OCHA | F9: Rania DAGASH-KAMARA, Assistant Executive Director Partnerships and Innovation - rania.dagash@wfp.org | G9: Laura Turner, Deputy Director of Emergency Coordination, WFP - Laura.Turner@wfp.org Hansjoerg Strohmeyer, Policy Director, OCHA - strohmeyerh@un.org | H9: WFP | I9: RBAs agree on a light, practical approach for more coherent work in fragile settings, clarifying complementary roles, choosing small number of priority countries | J9: 46052 | K9: In priority contexts, RBAs show clearer alignment in practice, with better sequencing and less duplication, and share a short lessons note with UN80 bodies | L9: 46386 | M9: Confirmation needed | N9: Confirmation on standing members; consider final timeline earlier than December
A10: 2 | B10: WP2: New Humanitarian Compact | C10: 23 | D10: Align agencies’ responsibilities: UNHCR/IOM on joint institutional approaches (incl. route-based programming) | E10: USG OCHA | F10: Filippo Grandi, United Nations High Commissioner for Refugees (UNHCR) - grandi@unhcr.org Amy Pope, Director General, International Organization for Migration (IOM) - dg@iom.int | G10: Shahrzad Tadjbakhsh, Director, Division of International Protection, UNHCR - tadjbakh@unhcr.org Ugochi Daniels, Deputy Director General for Operations, IOM - udaniels@iom.int Hansjoerg Strohmeyer, Policy Director, OCHA - strohmeyerh@un.org | H10: UNHCR;IOM | I10: UNHCR and IOM select 2-3 contexts needing clearer roles on mixed movements and agree on a light, context-specific approach to improve complementarity | J10: 46052 | K10: In those contexts, UNHCR and IOM show better complementarity on mixed movements – clearer roles, fewer parallels, better sequencing – and share lessons with UN80 | L10: 46386 | M10: Confirmation needed | N10: Consider final timeline earlier than December; confirmation on milestone definitions
A11: 2 | B11: WP2: New Humanitarian Compact | C11: 24 | D11: Align agencies’ responsibilities: UNICEF/WFP/UNHCR/IOM on beneficiary data | E11: USG OCHA | F11: Filippo Grandi, United Nations High Commissioner for Refugees (UNHCR) - grandi@unhcr.org Amy Pope, Director General, International Organization for Migration (IOM) - dg@iom.int Catherine Russell, Executive Director, UNICEF - crussell@unicef.org Cindy McCain, Executive Director, World Food Programme (WFP) - cindy.mccain@wfp.org | G11: Ryan Beech, WFP - Ryan.Beech@wfp.org Hansjoerg Strohmeyer, Policy Director, OCHA - strohmeyerh@un.org UNICEF/IOM/HCR - To Be Confirmed | H11: UNHCR;IOM;UNICEF;WFP | I11: Agencies endorse shared principles for beneficiary-data alignment and identify 1-2 contexts for early interoperability pilots across HOPE, PRIMES, SCOPE, BRAVE | J11: 46052 | K11: Early pilots show less duplication and better interoperability across beneficiary-data systems, with a short lessons-learned note shared with UN80 bodies | L11: 46386 | M11: Confirmation needed | N11: Confirmation on standing members; consider final timeline earlier than December
A12: 2 | B12: WP2: New Humanitarian Compact | C12: 25 | D12: Align agencies’ responsibilities: WHO/UNICEF/WFP on health and nutrition | E12: USG OCHA | F12: Catherine Russell, Executive Director, UNICEF - crussell@unicef.org Cindy McCain, Executive Director, World Food Programme (WFP) - cindy.mccain@wfp.org | G12: Ted Chaiban, Deputy Executive Director, UNICEF - tchaiban@unicef.org Ilaria Dettori, Director, Nutrition Services, WFP - ilaria.dettori@wfp.org Hansjoerg Strohmeyer, Policy Director, OCHA - strohmeyerh@un.org WHO - To Be Confirmed | H12: UNICEF;WFP | I12: Dedication discussion held with relevant agencies, with initial parameters agreed | J12: 46052 | K12: Clearly defined roles and responsibilities, with information disseminated at the field level and with Member States and Nutrition cluster partners | L12: 46386 | M12: Confirmation needed | N12: Confirmation on standing members; consider final timeline earlier than December
A13: 3 | B13: WP3: UNDP/UNOPS | C13: 26 | D13: Conduct a thorough assessment of the benefits of a merger between UNDP and UNOPS; analysis to be presented to the Executive Boards in February 2026 | E13: DSG;Administrator UNDP;ED UNOPS | F13: Amina Mohammed, DSG, amina.mohammed@un.org; Jorge Moreira Da Silva, USG UNOPS, jorge.moreiradasilva@unops.org; Alexander de Croo, USG UNDP, alexander.de.croo@undp.org | G13: Sonja Leighton-Kone, ASG, UNOPS, sonjalk@unops.org; Linda Maguire, ASG, UNDP, linda.maguire@undp.org; Rahul Malhotra, Director New York Office, UNOPS, rahulm@unops.org; Fiona Bayat-Renoux, Deputy Chief of Staff, UNDP, Fiona.bayat-renoux@undp.org; Jean-Philippe Bernardini, Senior Political Affairs Officer, EOSG, Bernardini@un.org | H13: EOSG (ODSG);UNDP;UNOPS | I13: Draft initial assessment analysis of the ‘as is’ with high level merger options, pros, cons, risk analysis for internal consultations completed | J13: 46040 | K13: Thorough assessment of selected option(s) provided to Member States and guidance given through a General Assembly decision | L13: 46264 | M13: Finalized
A14: 4 | B14: WP4: UNFPA/UN Women | C14: 27 | D14: Conduct a thorough assessment of the benefits of a merger of UNFPA and UN Women and their respective mandates | E14: DSG;ED UNFPA;ED UN Women | F14: Amina Mohammed, DSG, Amina.mohammed@un.org; Sima Bahous, Executive Director, UN Women sima.bahous@unwomen.org; Diene Keita, Executive Director, UNFPA, Keita@unfpa.org | G14: Jean Philippe Bernardini, Senior Political Affairs Officer, EOSG, bernardini@un.org; Sam Choritz, Chief of Staff, UNFPA, choritz@unfpa.org; Mohammad Naciri, Chief of Staff, UN Women, mohammad.naciri@unwomen.org | H14: EOSG (ODSG);UN Women;UNFPA | I14: Strategic merger assessment completed for internal consultations, including risk/benefit considerations | J14: 46052 | K14: By mid-2026, a thorough assessment is provided to Member States for a General Assembly decision | L14: 46233 | M14: Finalized
A15: 4 | B15: WP4: UNFPA/UN Women | C15: 28 | D15: Conduct a thorough assessment to consider options to optimize normative functions of UNFPA on population statistics and related activities, including those currently undertaken by DESA | E15: DSG;ED UNFPA;ED UN Women | F15: Amina Mohammed, DSG, Amina.mohammed@un.org; Sima Bahous, Executive Director, UN Women sima.bahous@unwomen.org; Diene Keita, Executive Director, UNFPA, Keita@unfpa.org | G15: Jean Philippe Bernardini, Senior Political Affairs Officer, bernardini@un.org; Sam Choritz, Chief of Staff, UNFPA, choritz@unfpa.org; Mohammad Naciri, Chief of Staff, UN Women, mohammad.naciri@unwomen.org | H15: EOSG (ODSG);UN Women;UNFPA | I15: Options for optimization of the UN’s work on population statistics and related activities finalized for Secretary-General's consideration and integrated in merger analysis | J15: 46052 | K15: A final assessment integrated into the UN Women/UNFPA merger process, as per timelines above | L15: 46233 | M15: Finalized
A16: 5 | B16: WP5: UNCT reconfiguration | C16: 39 | D16: Propose a model to reconfigure country teams via system-wide working group, chaired by the Deputy Secretary-General | E16: DSG | F16: Amina J. Mohammed, DSG, Amina.mohammed@un.org; Jorge Moreira Da Silva, USG UNOPS, jorge.moreiradasilva@unops.org | G16: Rahul Malhorta, Director, UNOPS, rahulm@unops.org; Jean Philippe Bernardini, Senior Political Affairs Officer, EOSG, bernardini@un.org | H16: EOSG (ODSG);UNOPS | I16: Outline of the draft proposals presented to the Secretary-General for guidance | J16: 46029 | K16: Member States taken action/decided on final set of proposals presented by the Secretary-General (report finalized by 31 May 2026 – TBC, depend on UN80 next reporting cycle) | L16: 46263 | M16: Finalized
A17: 5 | B17: WP5: UNCT reconfiguration | C17: 40 | D17: Strengthen and recalibrate the Resident Coordinator system to better leverage knowledge hubs, expertise-on-demand, and non-resident entities | E17: DSG | F17: Amina J. Mohammed, DSG, Amina.mohammed@un.org; Oscar Fernandez-Taranco, ASG DCO, fernandez-taranco@un.org | G17: Jean Philippe Bernardini, Senior Political Affairs Officer, EOSG, bernardini@un.org | H17: EOSG (ODSG);DCO | I17: The parameters for the recalibration of the RC system defined and being consulted with Member States (e.g., change in DCO structure, more tailored approach) | J17: 46052 | K17: All measures to recalibrate the RC system (DCO 2.0) implemented and a decision to enhance the funding model of the RC system successfully tabled in the General Assembly | L17: 46263 | M17: Finalized
A18: 6 | B18: WP6: Regional reset | C18: 36 | D18: Establish a system-wide working group, chaired by the Deputy Secretary-General, to develop proposals on how to advance a reset of regional capacities for sustainable development, incl. on how to institutionalize Regional Integrated Platforms | E18: DSG | F18: Amina J. Mohammed, DSG, Amina.mohammed@un.org; Izumi Nakamitsu, USG ODA, nakamitsu@un.org | G18: Jean Philippe Bernardini, Senior Political Affairs Officer, EOSG, bernardini@un.org | H18: EOSG (ODSG);ODA | I18: System-wide working group convened and draft outline finalized and shared with the Secretary-General for guidance | J18: 46029 | K18: All aspects of the regional reset under SG prerogative implemented and decisions taken by Member States on aspects requiring new mandates (report May 2026 - TBC, depend on UN80 next reporting cycle) | L18: 46263 | M18: Finalized
A19: 6 | B19: WP6: Regional reset | C19: 37 | D19: Systematize the practice of hosting regional capacities within the Regional Economic Commissions, starting with DCO regional directors and teams | E19: DSG | F19: Amina J. Mohammed, DSG, Amina.mohammed@un.org; Izumi Nakamitsu, USG ODA, nakamitsu@un.org; Oscar Fernandez Taranco, ASG DCO, fernandez-taranco@un.org | G19: Jean Philippe Bernardini, Senior Political Affairs Officer, EOSG, bernardini@un.org; Nadia Hadi, Chief of Staff, DCO, hadin@un.org; Thilmeeza Hussain, Director, Regional Commission Office, thilmeeza.hussain@un.org | H19: EOSG (ODSG);ODA;DCO | I19: Develop initial proposals for co-hosting for further consultation, taking into consideration the unique regional needs and contexts | J19: 46052 | K19: Relocation of respective offices to be hosted by RECs is complete or ongoing, according to implementation plan developed for each region by 29 May 2026 | L19: 46170 | M19: Finalized
A20: 7 | B20: WP7: Joint knowledge hubs | C20: 33 | D20: Establish Joint Knowledge Hubs to pool knowledge on key issues spread across UN development system entities and avoid duplications, including finding the best placed entities to co-leads (through joint mechanisms) | E20: USG DESA;SG UNCTAD | F20: Rebeca Grynspan, SG UNCTAD, rebeca.grynspan@unctad.org; LI Junhua, USG DESA, junhua.li@un.org | G20: Adnan Issa, Director Programme Management, UNCTAD, issa@unctad.org; Wai Min Kwok, Acting Chief Office of the USG, DESA, kwok@un.org; Carlos Razo, Senior Coordinator Office of the Secretary General, UNCTAD, carlos.razo@un.org; Guenther Gross, Senior Programme Management Officer Office of the USG, DESA, gross1@un.org | H20: DESA;UNCTAD | I20: The first meeting endorsed the concept note, agreed on hub list with leads, and committed to distinct value and collaboration with UN mechanisms | J20: 46052 | K20: Established hubs deliver coherent, efficient UN-wide support, integrating data and knowledge for policy coherence and innovative solutions | L20: 46386 | M20: Attention to timeline | N20: Review final deadline if intention is to demonstrate results from implementation before end 2026
A21: 8 | B21: WP8: Expertise-on-demand mechanism | C21: 34 | D21: Create a pro-active mechanism UN system-wide expertise on demand, particularly from specialized agencies and non-resident entities | E21: SG ITU | F21: Leads: ITU: Ms. Doreen Bogdan-Martin, Secretary-General (sgo@itu.int) UNDP Invited to co-Lead: Haoliang Xu, Acting Administrator (haoliang.xu@undp.org) Members: FAO: Mr. Qu Dongyu, Director General (director-general@fao.org; dongyu.qu@fao.org) ICAO: Mr. Juan Carlos Salazar, Secretary-General (OSGinbox@icao.int; jsalazar@icao.int) ILO: Mr. Gilbert F. Houngbo, Director General (ILODirector-General@ilo.org) UNESCO: Mr Khaled El-Enany, Director-General (dg.secretariat@unesco.org) UNIDO: Gerd Müller, Director General (ODG@unido.org) WHO: Mr. Tedros Adhanom Ghebreyesus, Director General (dgoffice@who.int WMO: Ms Celeste Saulo, Secretary-General (sgomm@wmo.int) ITC: Ms. Pamela Coke-Hamilton, Executive Director and ASG (cokehamilton@intracen.org); front office: Ascension Carrasco Rodriguez (carrasco@intracen.org) UN Women: Sima Bahous, Executive Director. Sima Sami Bahous (sima.bahous@unwomen.org) UNCTAD: Ms. Rebeca Grynspan, Secretary-General (rebeca.grynspan@unctad.org) UNCTAD: Ms. Rebeca Grynspan, Secretary-General (rebeca.grynspan@unctad.org) UNOPS: Mr. Jorge Moreira, Executive Director (jorge.moreiradasilva@unops.org) Regional Commissions: Mr. Claver Gatete, Coordinator of the Regional Commissions, ECA Executive Secretary (cgatete@un.org) Ms. Tatiana Molcean, Executive Secretary of ECE (tatiana.molcean@un.org) Mr. Mourad Wahba, Acting Executive of ESCWA Secretary (mourad.wahba@un.org) UNCTAD: Ms. Rebeca Grynspan, Secretary-General (rebeca.grynspan@unctad.org) | G21: Tomas Lamanauskas, DSG, ITU, dsg@itu.int; Linda Maquire, ASG/Director Bureau for Management Services, UNDP, linda.maguire@undp.org; Beth Crawford, ASG/Director Office of Strategy, Programme and Budget, FAO, beth.crawford@fao.org; Michiel Vreedenburgh, Chief Transformation Officer, ICAO, MVreedenburgh@icao.int; Laura Thompson, Assistant Director General External and Corporate Relations, ILO, thompsonl@ilo.org; Jennifer Linkins, Assistant Director-General for Administration and Management, UNESCO, j.linkins@unesco.org; Cecilia Ugaz Estrada, Deputy to the Director General, UNIDO, C.UGAZESTRADA@unido.org -tbc; Bruce Aylward, Senior Advisor to the Director-General, WHO, aylwardb@who.int; Ko Barrett, DSG, WMO, dsgo@wmo.int; Mondher Mimouni, Director Division of Market Development, ITC, mimouni@intracen.org; Nyaradzayi Gumbonzvanda. Deputy Executive Director Normative Support, System Coordination, Programme Results, UN Women, n.gumbonzvanda@unwomen.org; Rahul Malhotra, -, UNOPS, rahulm@unops.org; UNCTAD Tbc: Regional Commissions: Thilmeeza Hussain, -, ECA, thilmeeza.hussain@un.org; Aboubakri Diaw, -, ECA, diaw2@un.org; Paul John Ladd, -, ECE, paul.ladd@un.org; Maisaa Youssef, -, ESCWA, youssef8@un.org; Riwa Nasreddine, -, ESCWA, nasreddine@un.org; Support/Advisor: Jens Christian Wandel, SA Reform, jens.wandel@un.org | H21: ITU;UNDP;FAO;ICAO;ILO;UNESCO;UNIDO;WHO;WMO;ITC;UN Women;UNOPS;ECA;ECE;ESCWA;UNCTAD;SA Reform | I21: Concept endorsed (legal/financial assessment, catalogue design, and demand protocol and arrangements) | J21: 46080 | K21: EOD fully operational system-wide: expertise catalogue launched, protocols institutionalized, proven replacement of duplicative capacities | L21: 46375 | M21: Attention to timeline | N21: Review final deadline if intention is to demonstrate results from implementation before end 2026
A22: 8 | B22: WP8: Expertise-on-demand mechanism | C22: 54 | D22: Consolidate expertise across all pillars at the regional level as an extension of the expertise-on-demand mechanism outlined in the sustainable development pillar | E22: SG ITU | F22: Leads: ITU: Ms. Doreen Bogdan-Martin, Secretary-General (sgo@itu.int) UNDP Invited to co-Lead: Haoliang Xu, Acting Administrator (haoliang.xu@undp.org) Members: FAO: Mr. Qu Dongyu, Director General (director-general@fao.org; dongyu.qu@fao.org) ICAO: Mr. Juan Carlos Salazar, Secretary-General (OSGinbox@icao.int; jsalazar@icao.int) ILO: Mr. Gilbert F. Houngbo, Director General (ILODirector-General@ilo.org) UNESCO: Mr Khaled El-Enany, Director-General (dg.secretariat@unesco.org) UNIDO: Gerd Müller, Director General (ODG@unido.org) WHO: Mr. Tedros Adhanom Ghebreyesus, Director General (dgoffice@who.int) WMO: Ms Celeste Saulo, Secretary-General (sgomm@wmo.int) ITC: Ms. Pamela Coke-Hamilton, Executive Director and ASG (cokehamilton@intracen.org); front office: Ascension Carrasco Rodriguez (carrasco@intracen.org) UN Women: Sima Bahous, Executive Director. Sima Sami Bahous (sima.bahous@unwomen.org) UNCTAD: Ms. Rebeca Grynspan, Secretary-General (rebeca.grynspan@unctad.org) UNOPS: Mr. Jorge Moreira, Executive Director (jorge.moreiradasilva@unops.org) Regional Commissions: Mr. Claver Gatete, Coordinator of the Regional Commissions, ECA Executive Secretary (cgatete@un.org) Ms. Tatiana Molcean, Executive Secretary of ECE (tatiana.molcean@un.org) Mr. Mourad Wahba, Acting Executive of ESCWA Secretary (mourad.wahba@un.org) | G22: Tomas Lamanauskas, DSG, ITU, dsg@itu.int; Linda Maquire, ASG/Director Bureau for Management Services, UNDP, linda.maguire@undp.org; Beth Crawford, ASG/Director Office of Strategy, Programme and Budget, FAO, beth.crawford@fao.org; Michiel Vreedenburgh, Chief Transformation Officer, ICAO, MVreedenburgh@icao.int; Laura Thompson, Assistant Director General External and Corporate Relations, ILO, thompsonl@ilo.org; Jennifer Linkins, Assistant Director-General for Administration and Management, UNESCO, j.linkins@unesco.org; Cecilia Ugaz Estrada, Deputy to the Director General, UNIDO, C.UGAZESTRADA@unido.org -tbc; Bruce Aylward, Senior Advisor to the Director-General, WHO, aylwardb@who.int; Ko Barrett, DSG, WMO, dsgo@wmo.int; Mondher Mimouni, Director Division of Market Development, ITC, mimouni@intracen.org; Nyaradzayi Gumbonzvanda. Deputy Executive Director Normative Support, System Coordination, Programme Results, UN Women, n.gumbonzvanda@unwomen.org; Rahul Malhotra, -, UNOPS, rahulm@unops.org; UNCTAD Tbc: Regional Commissions: Thilmeeza Hussain, -, ECA, thilmeeza.hussain@un.org; Aboubakri Diaw, -, ECA, diaw2@un.org; Paul John Ladd, -, ECE, paul.ladd@un.org; Maisaa Youssef, -, ESCWA, youssef8@un.org; Riwa Nasreddine, -, ESCWA, nasreddine@un.org; Support/Advisor: Jens Christian Wandel, SA Reform, jens.wandel@un.org | H22: ITU;UNDP;FAO;ICAO;ILO;UNESCO;UNIDO;WHO;WMO;ITC;UN Women;UNOPS;ECA;ECE;ESCWA;UNCTAD;SA Reform | I22: Concept endorsed (legal/financial assessment, catalogue design, and demand protocol and arrangements) | J22: 46080 | K22: EOD fully operational system-wide: expertise catalogue launched, protocols institutionalized, proven replacement of duplicative capacities | L22: 46375 | M22: Attention to timeline | N22: Review final deadline if intention is to demonstrate results from implementation before end 2026
